Workbook

Sheet 仪表盘
A1: 14维机构级宏观监控模型｜仪表盘
A4: 更新日 | B4: =Inputs!B2 | D4: 总分 | E4: =Scores!D70 | G4: 状态 | H4: =Scores!F70 | J4: 触发预警 | K4: =COUNTIF(Alerts!E6:E12,"YES")
A6: 执行摘要
A7: 模型定位 | B7: 用 14 个维度把“增长 / 通胀 / 流动性 / 风险 / 财政 / 外部 / 主题”放在一张图里。
A8: 当前阅读方式 | B8: 先看总分与状态，再看预警灯号，最后看维度贡献与拖累项。
A9: 建议动作 | B9: 若预警>=2条且总分跌入45以下，建议转向防御；若总分持续站上60且预警清零，可提高风险偏好。
A12: 维度 | B12: 权重 | C12: 维度分 | D12: 贡献 | E12: 层级 | F12: 更新频率 | H12: 关键看点
A13: =Scores!B55 | B13: =Scores!C55/100 | C13: =Scores!D55 | D13: =Scores!E55 | E13: =INDEX(Dimensions!$C$2:$C$15,MATCH(INDEX(Scores!$A$55:$A$68,ROW()-12),Dimensions!$B$2:$B$15,0)) | F13: =INDEX(Dimensions!$F$2:$F$15,MATCH(INDEX(Scores!$A$55:$A$68,ROW()-12),Dimensions!$B$2:$B$15,0)) | H13: 前三支撑 | J13: 前三拖累
A14: =Scores!B56 | B14: =Scores!C56/100 | C14: =Scores!D56 | D14: =Scores!E56 | E14: =INDEX(Dimensions!$C$2:$C$15,MATCH(INDEX(Scores!$A$55:$A$68,ROW()-12),Dimensions!$B$2:$B$15,0)) | F14: =INDEX(Dimensions!$F$2:$F$15,MATCH(INDEX(Scores!$A$55:$A$68,ROW()-12),Dimensions!$B$2:$B$15,0)) | H14: =INDEX($A$13:$A$26,MATCH(LARGE($D$13:$D$26,1),$D$13:$D$26,0)) | I14: =INDEX($D$13:$D$26,MATCH($H14,$A$13:$A$26,0)) | J14: =INDEX($A$13:$A$26,MATCH(SMALL($D$13:$D$26,1),$D$13:$D$26,0)) | K14: =INDEX($D$13:$D$26,MATCH($J14,$A$13:$A$26,0))
A15: =Scores!B57 | B15: =Scores!C57/100 | C15: =Scores!D57 | D15: =Scores!E57 | E15: =INDEX(Dimensions!$C$2:$C$15,MATCH(INDEX(Scores!$A$55:$A$68,ROW()-12),Dimensions!$B$2:$B$15,0)) | F15: =INDEX(Dimensions!$F$2:$F$15,MATCH(INDEX(Scores!$A$55:$A$68,ROW()-12),Dimensions!$B$2:$B$15,0)) | H15: =INDEX($A$13:$A$26,MATCH(LARGE($D$13:$D$26,2),$D$13:$D$26,0)) | I15: =INDEX($D$13:$D$26,MATCH($H15,$A$13:$A$26,0)) | J15: =INDEX($A$13:$A$26,MATCH(SMALL($D$13:$D$26,2),$D$13:$D$26,0)) | K15: =INDEX($D$13:$D$26,MATCH($J15,$A$13:$A$26,0))
A16: =Scores!B58 | B16: =Scores!C58/100 | C16: =Scores!D58 | D16: =Scores!E58 | E16: =INDEX(Dimensions!$C$2:$C$15,MATCH(INDEX(Scores!$A$55:$A$68,ROW()-12),Dimensions!$B$2:$B$15,0)) | F16: =INDEX(Dimensions!$F$2:$F$15,MATCH(INDEX(Scores!$A$55:$A$68,ROW()-12),Dimensions!$B$2:$B$15,0)) | H16: =INDEX($A$13:$A$26,MATCH(LARGE($D$13:$D$26,3),$D$13:$D$26,0)) | I16: =INDEX($D$13:$D$26,MATCH($H16,$A$13:$A$26,0)) | J16: =INDEX($A$13:$A$26,MATCH(SMALL($D$13:$D$26,3),$D$13:$D$26,0)) | K16: =INDEX($D$13:$D$26,MATCH($J16,$A$13:$A$26,0))
A17: =Scores!B59 | B17: =Scores!C59/100 | C17: =Scores!D59 | D17: =Scores!E59 | E17: =INDEX(Dimensions!$C$2:$C$15,MATCH(INDEX(Scores!$A$55:$A$68,ROW()-12),Dimensions!$B$2:$B$15,0)) | F17: =INDEX(Dimensions!$F$2:$F$15,MATCH(INDEX(Scores!$A$55:$A$68,ROW()-12),Dimensions!$B$2:$B$15,0))
A18: =Scores!B60 | B18: =Scores!C60/100 | C18: =Scores!D60 | D18: =Scores!E60 | E18: =INDEX(Dimensions!$C$2:$C$15,MATCH(INDEX(Scores!$A$55:$A$68,ROW()-12),Dimensions!$B$2:$B$15,0)) | F18: =INDEX(Dimensions!$F$2:$F$15,MATCH(INDEX(Scores!$A$55:$A$68,ROW()-12),Dimensions!$B$2:$B$15,0)) | H18: 预警明细
A19: =Scores!B61 | B19: =Scores!C61/100 | C19: =Scores!D61 | D19: =Scores!E61 | E19: =INDEX(Dimensions!$C$2:$C$15,MATCH(INDEX(Scores!$A$55:$A$68,ROW()-12),Dimensions!$B$2:$B$15,0)) | F19: =INDEX(Dimensions!$F$2:$F$15,MATCH(INDEX(Scores!$A$55:$A$68,ROW()-12),Dimensions!$B$2:$B$15,0)) | H19: =Alerts!C6 | K19: =Alerts!E6 | L19: YES=触发
A20: =Scores!B62 | B20: =Scores!C62/100 | C20: =Scores!D62 | D20: =Scores!E62 | E20: =INDEX(Dimensions!$C$2:$C$15,MATCH(INDEX(Scores!$A$55:$A$68,ROW()-12),Dimensions!$B$2:$B$15,0)) | F20: =INDEX(Dimensions!$F$2:$F$15,MATCH(INDEX(Scores!$A$55:$A$68,ROW()-12),Dimensions!$B$2:$B$15,0)) | H20: =Alerts!C7 | K20: =Alerts!E7
A21: =Scores!B63 | B21: =Scores!C63/100 | C21: =Scores!D63 | D21: =Scores!E63 | E21: =INDEX(Dimensions!$C$2:$C$15,MATCH(INDEX(Scores!$A$55:$A$68,ROW()-12),Dimensions!$B$2:$B$15,0)) | F21: =INDEX(Dimensions!$F$2:$F$15,MATCH(INDEX(Scores!$A$55:$A$68,ROW()-12),Dimensions!$B$2:$B$15,0)) | H21: =Alerts!C8 | K21: =Alerts!E8
A22: =Scores!B64 | B22: =Scores!C64/100 | C22: =Scores!D64 | D22: =Scores!E64 | E22: =INDEX(Dimensions!$C$2:$C$15,MATCH(INDEX(Scores!$A$55:$A$68,ROW()-12),Dimensions!$B$2:$B$15,0)) | F22: =INDEX(Dimensions!$F$2:$F$15,MATCH(INDEX(Scores!$A$55:$A$68,ROW()-12),Dimensions!$B$2:$B$15,0)) | H22: =Alerts!C9 | K22: =Alerts!E9
A23: =Scores!B65 | B23: =Scores!C65/100 | C23: =Scores!D65 | D23: =Scores!E65 | E23: =INDEX(Dimensions!$C$2:$C$15,MATCH(INDEX(Scores!$A$55:$A$68,ROW()-12),Dimensions!$B$2:$B$15,0)) | F23: =INDEX(Dimensions!$F$2:$F$15,MATCH(INDEX(Scores!$A$55:$A$68,ROW()-12),Dimensions!$B$2:$B$15,0)) | H23: =Alerts!C10 | K23: =Alerts!E10
A24: =Scores!B66 | B24: =Scores!C66/100 | C24: =Scores!D66 | D24: =Scores!E66 | E24: =INDEX(Dimensions!$C$2:$C$15,MATCH(INDEX(Scores!$A$55:$A$68,ROW()-12),Dimensions!$B$2:$B$15,0)) | F24: =INDEX(Dimensions!$F$2:$F$15,MATCH(INDEX(Scores!$A$55:$A$68,ROW()-12),Dimensions!$B$2:$B$15,0)) | H24: =Alerts!C11 | K24: =Alerts!E11
A25: =Scores!B67 | B25: =Scores!C67/100 | C25: =Scores!D67 | D25: =Scores!E67 | E25: =INDEX(Dimensions!$C$2:$C$15,MATCH(INDEX(Scores!$A$55:$A$68,ROW()-12),Dimensions!$B$2:$B$15,0)) | F25: =INDEX(Dimensions!$F$2:$F$15,MATCH(INDEX(Scores!$A$55:$A$68,ROW()-12),Dimensions!$B$2:$B$15,0)) | H25: =Alerts!C12 | K25: =Alerts!E12
A26: =Scores!B68 | B26: =Scores!C68/100 | C26: =Scores!D68 | D26: =Scores!E68 | E26: =INDEX(Dimensions!$C$2:$C$15,MATCH(INDEX(Scores!$A$55:$A$68,ROW()-12),Dimensions!$B$2:$B$15,0)) | F26: =INDEX(Dimensions!$F$2:$F$15,MATCH(INDEX(Scores!$A$55:$A$68,ROW()-12),Dimensions!$B$2:$B$15,0))

Sheet 监控仪表盘
A1: 14维机构级宏观监控模型｜仪表盘
A4: 模型更新日 | B4: =Inputs!B2 | D4: 总分 | E4: =IF(Inputs!B2="","",Scores!D70) | F4: 预警统计 | G4: 状态 | H4: =IF(Inputs!B2="","",Scores!F70)
F5: =COUNTIF(Alerts!E6:E12,"YES") | G5: 条触发
A6: 维度 | B6: 权重 | C6: 维度分 | D6: 贡献 | F6: 主题 | G6: 说明
A7: =Scores!B55 | B7: =Scores!C55/100 | C7: =Scores!D55 | D7: =Scores!E55 | F7: =Dimensions!C2 | G7: =Dimensions!E2
A8: =Scores!B56 | B8: =Scores!C56/100 | C8: =Scores!D56 | D8: =Scores!E56 | F8: =Dimensions!C3 | G8: =Dimensions!E3
A9: =Scores!B57 | B9: =Scores!C57/100 | C9: =Scores!D57 | D9: =Scores!E57 | F9: =Dimensions!C4 | G9: =Dimensions!E4
A10: =Scores!B58 | B10: =Scores!C58/100 | C10: =Scores!D58 | D10: =Scores!E58 | F10: =Dimensions!C5 | G10: =Dimensions!E5
A11: =Scores!B59 | B11: =Scores!C59/100 | C11: =Scores!D59 | D11: =Scores!E59 | F11: =Dimensions!C6 | G11: =Dimensions!E6
A12: =Scores!B60 | B12: =Scores!C60/100 | C12: =Scores!D60 | D12: =Scores!E60 | F12: =Dimensions!C7 | G12: =Dimensions!E7
A13: =Scores!B61 | B13: =Scores!C61/100 | C13: =Scores!D61 | D13: =Scores!E61 | F13: =Dimensions!C8 | G13: =Dimensions!E8
A14: =Scores!B62 | B14: =Scores!C62/100 | C14: =Scores!D62 | D14: =Scores!E62 | F14: =Dimensions!C9 | G14: =Dimensions!E9
A15: =Scores!B63 | B15: =Scores!C63/100 | C15: =Scores!D63 | D15: =Scores!E63 | F15: =Dimensions!C10 | G15: =Dimensions!E10
A16: =Scores!B64 | B16: =Scores!C64/100 | C16: =Scores!D64 | D16: =Scores!E64 | F16: =Dimensions!C11 | G16: =Dimensions!E11
A17: =Scores!B65 | B17: =Scores!C65/100 | C17: =Scores!D65 | D17: =Scores!E65 | F17: =Dimensions!C12 | G17: =Dimensions!E12
A18: =Scores!B66 | B18: =Scores!C66/100 | C18: =Scores!D66 | D18: =Scores!E66 | F18: =Dimensions!C13 | G18: =Dimensions!E13
... A20: =Scores!B68 | B20: =Scores!C68/100 | C20: =Scores!D68 | D20: =Scores!E68 | F20: =Dimensions!C15 | G20: =Dimensions!E15
A22: 使用提示：蓝色表签用于录入与参数；橙色/红色表签用于结果与预警。样例数据版仅作演示，不构成投资判断。

Sheet 数据源映射
A1: 14维机构级模型｜数据源映射与抓取口径
A3: 用途 | B3: 把每个指标的“主数据源 / 备选源 / 建议代码 / 更新频率 / 单位 / 抓取说明”统一到一张表，便于团队周更。
A5: IndicatorCode | B5: DimensionID | C5: IndicatorName | D5: 主数据源 | E5: 建议系列代码/字段 | F5: 备选源 | G5: 更新频率 | H5: 单位 | I5: 抓取说明 | J5: 备注
A6: YC_10Y3M | B6: D01 | C6: 10Y-3M利差（bps） | D6: FRED (H.15) | E6: DGS10 & DGS3MO | F6: https://fred.stlouisfed.org/series/DGS10 | G6: Daily | H6: bps | I6: 建议固定单一主源，减少口径切换。
A7: SOFR | B7: D01 | C7: SOFR（%） | D7: NY Fed / FRED | E7: SOFR | F7: https://fred.stlouisfed.org/series/SOFR | G7: Daily | H7: % | I7: 建议固定单一主源，减少口径切换。
A8: FED_ASSETS | B8: D01 | C8: 美联储总资产（$T） | D8: FRED (H.4.1) | E8: WALCL | F8: https://fred.stlouisfed.org/series/WALCL | G8: Weekly | H8: $T | I8: 建议固定单一主源，减少口径切换。
A9: NET_LIQ_PROXY | B9: D01 | C9: 净流动性代理（自定义） | D9: 自定义（FRED / Treasury / NY Fed） | E9: WALCL, WTREGEN, RRPONTSYD | F9: BTFP/准备金数据 | G9: Weekly | H9: index | I9: 推荐公式：Fed总资产 - TGA - RRP；先统一单位后再填入 Inputs。 | J9: 最好保留你的内部版本定义
A10: GDP_QOQ_SAAR | B10: D02 | C10: 实际GDP环比折年（%） | D10: BEA | E10: GDP | F10: FRED | G10: Quarterly | H10: % | I10: 优先用官方首发/修订值；保持同一版次。
A11: PMI_MAN | B11: D02 | C11: 制造业PMI | D11: ISM/S&P | E11: PMI | F11: S&P Global / Conference Board | G11: Monthly | H11: index | I11: 软数据易波动，建议用3M均值。
A12: CLAIMS_4WMA | B12: D02 | C12: 初请失业金四周均值 | D12: FRED | E12: IC4WSA | F12: https://fred.stlouisfed.org/series/IC4WSA | G12: Weekly | H12: k | I12: 建议固定单一主源，减少口径切换。
A13: LEI | B13: D02 | C13: 领先指标（LEI）同比（%） | D13: Conference Board | E13: LEI YoY | F13: https://www.conference-board.org/ | G13: Monthly | H13: % | I13: 建议固定单一主源，减少口径切换。
A14: CORE_CPI_YOY | B14: D03 | C14: 核心CPI同比（%） | D14: BLS/FRED | E14: CPILFESL | F14: https://fred.stlouisfed.org/series/CPILFESL | G14: Monthly | H14: % | I14: 建议固定单一主源，减少口径切换。
A15: CORE_PCE_YOY | B15: D03 | C15: 核心PCE同比（%） | D15: BEA/FRED | E15: PCEPILFE | F15: FRED | G15: Monthly | H15: % | I15: 优先用官方首发/修订值；保持同一版次。
A16: BREAKEVEN_5Y5Y | B16: D03 | C16: 5Y5Y通胀预期（%） | D16: FRED | E16: T5YIFR | F16: https://fred.stlouisfed.org/series/T5YIFR | G16: Daily | H16: % | I16: 建议固定单一主源，减少口径切换。
A17: UNRATE | B17: D04 | C17: 失业率（%） | D17: BLS/FRED | E17: UNRATE | F17: https://fred.stlouisfed.org/series/UNRATE | G17: Monthly | H17: % | I17: 建议固定单一主源，减少口径切换。
A18: WAGE_GROWTH | B18: D04 | C18: 平均时薪同比（%） | D18: BLS/FRED | E18: CES0500000003 | F18: https://fred.stlouisfed.org/series/CES0500000003 | G18: Monthly | H18: % | I18: 建议固定单一主源，减少口径切换。
A19: CC_DELINQ | B19: D04 | C19: 信用卡拖欠率（%） | D19: FRED | E19: DRCCLACBS | F19: https://fred.stlouisfed.org/series/DRCCLACBS | G19: Quarterly | H19: % | I19: 建议固定单一主源，减少口径切换。
A20: REAL_DISP_INC | B20: D04 | C20: 实际可支配收入同比（%） | D20: BEA/FRED | E20: DSPIC96 | F20: https://fred.stlouisfed.org/series/DSPIC96 | G20: Monthly | H20: % | I20: 建议固定单一主源，减少口径切换。
A21: SPX_FWD_PE | B21: D05 | C21: 标普500 Forward P/E（x） | D21: FactSet/S&P | E21: FWD PE | G21: Weekly | H21: x | I21: 建议固定单一主源，减少口径切换。
A22: EPS_REV_BREADTH | B22: D05 | C22: EPS修正广度（上调-下调，%） | D22: IBES/FactSet | E22: EPS rev | G22: Weekly | H22: % | I22: 建议固定单一主源，减少口径切换。
A23: HY_OAS | B23: D05 | C23: 高收益信用利差OAS（bps） | D23: FRED | E23: BAMLH0A0HYM2 | F23: https://fred.stlouisfed.org/series/BAMLH0A0HYM2 | G23: Daily | H23: bps | I23: 建议固定单一主源，减少口径切换。
A24: MORTGAGE_30Y | B24: D06 | C24: 30年按揭利率（%） | D24: Freddie Mac | E24: PMMS | F24: https://www.freddiemac.com/pmms | G24: Weekly | H24: % | I24: 建议固定单一主源，减少口径切换。
A25: EXIST_HOME_SALES | B25: D06 | C25: 成屋销售折年（百万套） | D25: NAR | E25: EHS | F25: https://www.nar.realtor/ | G25: Monthly | H25: M | I25: 建议固定单一主源，减少口径切换。
A26: HOUSING_STARTS | B26: D06 | C26: 新屋开工（百万套） | D26: Census/FRED | E26: HOUST | F26: https://fred.stlouisfed.org/series/HOUST | G26: Monthly | H26: M | I26: 建议固定单一主源，减少口径切换。
A27: VIX | B27: D07 | C27: VIX | D27: CBOE/FRED | E27: VIXCLS | F27: https://fred.stlouisfed.org/series/VIXCLS | G27: Daily | H27: index | I27: 建议固定单一主源，减少口径切换。
A28: MOVE | B28: D07 | C28: MOVE | D28: ICE | E28: MOVE | G28: Daily | H28: index | I28: 建议固定单一主源，减少口径切换。
A29: SPX_DD_3M | B29: D07 | C29: 标普500近3个月最大回撤（%） | D29: User Calc | E29: N/A | G29: Daily | H29: % | I29: 建议固定单一主源，减少口径切换。
A30: DXY | B30: D08 | C30: 美元指数DXY | D30: ICE/公开行情 | E30: DXY | G30: Daily | H30: index | I30: 建议固定单一主源，减少口径切换。
A31: US_JP_10Y_SPREAD | B31: D08 | C31: 美日10Y利差（bps） | D31: FRED/BOJ | E31: N/A | G31: Daily | H31: bps | I31: 建议固定单一主源，减少口径切换。
A32: CAPITAL_FLOWS | B32: D08 | C32: 海外净买入美国资产（自定义） | D32: Treasury TIC/EPFR | E32: TIC/EPFR | G32: Monthly | H32: $B | I32: 建议固定单一主源，减少口径切换。
A33: DEFICIT_GDP | B33: D09 | C33: 财政赤字/GDP（%） | D33: CBO | E33: CBO baseline | F33: https://www.cbo.gov/publication/62105 | G33: Annual/Quarterly | H33: % | I33: 建议固定单一主源，减少口径切换。
A34: DEBT_GDP | B34: D09 | C34: 债务/GDP（%） | D34: CBO | E34: CBO baseline | F34: https://www.cbo.gov/publication/62105 | G34: Annual | H34: % | I34: 建议固定单一主源，减少口径切换。
A35: INT_REV | B35: D09 | C35: 利息支出/财政收入（%） | D35: Treasury/CBO | E35: N/A | G35: Annual | H35: % | I35: 建议固定单一主源，减少口径切换。
A36: FCI | B36: D10 | C36: 金融条件指数（FCI） | D36: GS/Chicago Fed | E36: FCI | G36: Weekly | H36: index | I36: 建议固定单一主源，减少口径切换。
A37: BANK_LENDING | B37: D10 | C37: 银行信贷增速（% YoY） | D37: Fed H.8 | E37: H.8 | G37: Weekly/Monthly | H37: % | I37: 建议固定单一主源，减少口径切换。
A38: TED_SPREAD | B38: D10 | C38: TED利差（bps） | D38: FRED | E38: TEDRATE | F38: https://fred.stlouisfed.org/series/TEDRATE | G38: Daily | H38: bps | I38: 建议固定单一主源，减少口径切换。
A39: WTI | B39: D11 | C39: WTI原油（$/桶） | D39: NYMEX/公开行情 | E39: WTI | G39: Daily | H39: $/bbl | I39: 建议固定单一主源，减少口径切换。
A40: CRB | B40: D11 | C40: 大宗商品指数（CRB）同比（%） | D40: Refinitiv/公开 | E40: CRB | G40: Weekly | H40: % | I40: 建议固定单一主源，减少口径切换。
A41: GPR | B41: D11 | C41: 地缘政治风险指数（GPR） | D41: Caldara & Iacoviello | E41: GPR | F41: 官方站点 / FRED / PolicyUncertainty | G41: Monthly | H41: index | I41: 若无稳定自动抓取，可改为月度手工更新。
A42: CB_CONS_CONF | B42: D12 | C42: 消费者信心指数 | D42: Conference Board | E42: Consumer Confidence | F42: https://www.conference-board.org/ | G42: Monthly | H42: index | I42: 建议固定单一主源，减少口径切换。
...

Sheet API代码映射
A1: 常用数据源代码映射
A3: Source | B3: 典型指标 | C3: 建议代码/端点 | D3: 官网/入口 | E3: 更新时间 | F3: 单位规范 | G3: 优先级 | H3: 说明
A4: FRED | B4: 利率、曲线、Fed资产、失业率、信用利差 | C4: DGS10 / DGS3MO / SOFR / WALCL / UNRATE / BAMLH0A0HYM2 | D4: https://fred.stlouisfed.org/ | E4: Daily/Weekly/Monthly | F4: % / bps / $bn | G4: 高 | H4: 宏观主源，最适合做机构版周更
A5: BEA | B5: GDP、PCE、可支配收入 | C5: NIPA Tables / GDP / PCEPI | D5: https://www.bea.gov/ | E5: Quarterly/Monthly | F5: % / $bn | G5: 高 | H5: 增长与收入类优先官方
A6: BLS | B6: CPI、工资、就业 | C6: CUSR... / CES... | D6: https://www.bls.gov/ | E6: Monthly | F6: % / index / k | G6: 高 | H6: 通胀与就业官方源
A7: Treasury | B7: TGA、财政收支、债务 | C7: Daily Treasury Statement / Debt to the Penny | D7: https://fiscaldata.treasury.gov/ | E7: Daily/Monthly | F7: $bn / %GDP | G7: 高 | H7: 财政与流动性必备
A8: NY Fed | B8: SOFR、RRP、调查预期 | C8: SOFR / ON RRP | D8: https://www.newyorkfed.org/ | E8: Daily | F8: % / $bn | G8: 高 | H8: 货币市场主源
A9: Freddie Mac | B9: 30Y Mortgage Rate | C9: PMMS | D9: https://www.freddiemac.com/pmms | E9: Weekly | F9: % | G9: 高 | H9: 地产融资成本
A10: NAR / Census | B10: 成屋销售、新屋开工 | C10: Existing Home Sales / HOUST | D10: https://www.nar.realtor/ | E10: Monthly | F10: mn saar | G10: 中 | H10: 地产景气
A11: FactSet / Bloomberg | B11: Forward P/E、EPS修正 | C11: Custom field | D11: 终端/订阅 | E11: Daily/Weekly | F11: x / % | G11: 高 | H11: 企业估值与盈利
A12: ICE / CBOE | B12: DXY / MOVE / VIX | C12: DXY / MOVE / VIX | D12: 官网/终端 | E12: Daily | F12: index | G12: 中 | H12: 市场状态
A13: Conference Board / NFIB | B13: 消费者/CEO/小企业信心 | C13: CCI / CEO Confidence / NFIB | D13: 官网 | E13: Monthly/Quarterly | F13: index | G13: 中 | H13: 软数据
A14: CoinMarketCap / DefiLlama | B14: BTC / USDC / stablecoin | C14: asset endpoint | D14: 官网/API | E14: Daily | F14: $ / $bn | G14: 低 | H14: 主题面板，不宜高权重

Sheet 模型总表
A1: 宏观经济监控模型（最终版14维）｜样例数据版
A2: 用途：机构级宏观监控 / 投资决策 / 月度或周度复盘。原则：只将可验证、可持续抓取、可历史回溯的指标纳入总分。
A4: 维度ID | B4: 维度名称 | C4: 层级 | D4: 权重 | E4: 核心监控指标（建议） | F4: 更新频率 | G4: 评分方式 | H4: 备注
A5: D01 | B5: 货币政策与流动性 | C5: Core Macro | D5: 12% | E5: 10Y-3M利差；SOFR/EFFR；美联储总资产；净流动性代理（Fed-TGA-RRP） | F5: 日/周 | G5: 线性+截尾 | H5: 建议重点跟踪净流动性而非单独看TGA
A6: D02 | B6: 增长与前瞻 | C6: Core Macro | D6: 11% | E6: 实际GDP环比折年；制造业PMI；初请失业金4周均值；LEI同比 | F6: 周/月/季 | G6: 区间最优+线性 | H6: 前瞻指标权重应高于滞后指标
A7: D03 | B7: 通胀与价格压力 | C7: Core Macro | D7: 10% | E7: 核心CPI；核心PCE；5Y5Y通胀预期 | F7: 月 | G7: 区间最优 | H7: 建议将2%~2.5%设为较优区间
A8: D04 | B8: 就业与居民部门 | C8: Core Macro | D8: 10% | E8: 失业率；工资增速；信用卡拖欠率；实际可支配收入同比 | F8: 月/季 | G8: 线性+区间 | H8: 兼顾就业强弱与居民资产负债表压力
A9: D05 | B9: 企业盈利与信用 | C9: Core Macro | D9: 8% | E9: 标普500 Forward P/E；EPS修正广度；HY OAS | F9: 日/周/月 | G9: 线性+区间 | H9: 删除难以稳定复现的主观ERP假设
A10: D06 | B10: 房地产与利率敏感部门 | C10: Core Macro | D10: 6% | E10: 30年按揭利率；成屋销售；新屋开工 | F10: 周/月 | G10: 线性+区间 | H10: 同时看融资成本、交易量和供给
A11: D07 | B11: 风险偏好与跨资产波动 | C11: Market Mapping | D11: 6% | E11: VIX；MOVE；3个月最大回撤 | F11: 日/周 | G11: LowerBetter | H11: 适合作为市场映射维度
A12: D08 | B12: 外部部门与美元条件 | C12: Policy/External | D12: 7% | E12: DXY/REER；美日利差；海外净买入美国资产 | F12: 周/月 | G12: 区间最优 | H12: 贸易差额建议配合资本流入一起看
A13: D09 | B13: 财政政策与债务约束 | C13: Policy/External | D13: 8% | E13: 财政赤字/GDP；债务/GDP；利息支出/财政收入 | F13: 月/季/年 | G13: LowerBetter | H13: 利息负担通常比债务存量更关键
A14: D10 | B14: 金融条件与信用传导 | C14: Policy/External | D14: 6% | E14: FCI；银行信贷增速；TED利差 | F14: 周/月 | G14: 线性 | H14: 关注政策如何传导至实体融资条件
A15: D11 | B15: 大宗商品与能源/地缘风险 | C15: External Shock | D15: 5% | E15: WTI；CRB同比；GPR指数 | F15: 日/月 | G15: 区间最优 | H15: 地缘风险必须使用明确数值序列
... A18: D14 | B18: 加密与稳定币流动性 | C18: Theme | D18: 1% | E18: BTC；USDC市值；稳定币总市值 | F18: 日/周 | G18: 线性/趋势 | H18: 建议长期改为趋势与波动组合
A21: 评分规则（建议正式版） | B21: 单指标：使用历史分位数或线性/区间最优映射到0–100分；维度分：维度内加权平均；总分：Σ(维度分×权重)。
A22: 状态区间 | B22: 75–100 扩张偏热；60–75 温和扩张；45–60 中性脆弱；30–45 防御区；0–30 衰退/危机区。
A23: 使用建议 | B23: 总分用于战略判断；Alerts页红黄灯用于战术风控；AI/Crypto 建议作为主题景气面板而非主宏观驱动。
A24: 关联工作表 | B24: Dimensions：维度定义；Indicators：指标库与参数；Inputs：填写最新值；Scores：自动算分；Alerts：预警触发。

Sheet README
A1: 宏观经济监控模型（机构级）— 带样例数据版
A3: 使用方式（建议）
A4: 1) 本工作簿已预填一版截至 2026-03-01 左右的演示样例值。 2) 样例值主要用于展示打分框架如何运行，不代表完整投资建议。 3) 替换 Inputs 中蓝色单元格后，Scores / 仪表盘 / Alerts 会自动更新。
A6: 评分口径（默认）
A7: 默认使用线性刻度并做0-100截尾： HigherBetter: (x-Worst)/(Best-Worst)*100 LowerBetter: (Worst-x)/(Worst-Best)*100 TargetBand: 区间内100分，向两侧线性衰减至WorstLow/WorstHigh为0分。 你也可以在 Indicators 表把 ScaleType 改成 Percentile（需要你自行引入历史分位数计算模块）。
A9: 颜色约定
A10: 蓝色：可编辑输入/可调参数；黑色：公式计算；橙色/红色：预警/异常。
A12: 新增工作表 | B12: 数据源映射 / API代码映射 / 董事会Dashboard
A13: 建议使用顺序 | B13: 1) Inputs填数 2) Scores看分 3) Alerts看灯号 4) 董事会Dashboard汇报
A14: 维护建议 | B14: 优先锁定宏观主源（FRED/BEA/BLS/Treasury），主题面板固定单一数据源避免口径跳变。

Sheet Dimensions
A1: DimensionID | B1: DimensionName | C1: Tier | D1: Weight(%) | E1: Definition | F1: Typical Update
A2: D01 | B2: 货币政策与流动性 | C2: Core Macro | D2: 12 | E2: 利率曲线、短端资金利率、央行资产负债表与净流动性。 | F2: Daily/Weekly
A3: D02 | B3: 增长与前瞻 | C3: Core Macro | D3: 11 | E3: GDP/PMI/订单/初请等前瞻增长信号。 | F3: Weekly/Monthly/Quarterly
A4: D03 | B4: 通胀与价格压力 | C4: Core Macro | D4: 10 | E4: 核心通胀与通胀预期，判断政策约束与利润压力。 | F4: Monthly
A5: D04 | B5: 就业与居民部门 | C5: Core Macro | D5: 10 | E5: 就业、收入与居民信用压力。 | F5: Monthly/Quarterly
A6: D05 | B6: 企业盈利与信用 | C6: Core Macro | D6: 8 | E6: 盈利预期修正与信用利差/违约压力。 | F6: Daily/Weekly/Monthly
A7: D06 | B7: 房地产与利率敏感部门 | C7: Core Macro | D7: 6 | E7: 按揭利率、成交与开工，反映利率传导。 | F7: Weekly/Monthly
A8: D07 | B8: 风险偏好与跨资产波动 | C8: Market Mapping | D8: 6 | E8: VIX/MOVE/信用利差等市场风险映射。 | F8: Daily/Weekly
A9: D08 | B9: 外部部门与美元条件 | C9: Policy & External | D9: 7 | E9: DXY/利差/资本流动等外部融资条件。 | F9: Daily/Monthly
A10: D09 | B10: 财政政策与债务约束 | C10: Policy & External | D10: 8 | E10: 赤字、利息负担与债务路径。 | F10: Quarterly/Annual
A11: D10 | B11: 金融条件与信用传导 | C11: Core Macro | D11: 6 | E11: 金融条件指数、银行信贷供给与资金面压力。 | F11: Weekly/Monthly
A12: D11 | B12: 大宗商品与能源/地缘风险 | C12: External/Commodities | D12: 5 | E12: 油价/商品与地缘风险对通胀与增长的冲击。 | F12: Daily/Monthly
A13: D12 | B13: 信心与不确定性 | C13: Soft Data | D13: 6 | E13: 消费者/企业信心与政策不确定性。 | F13: Monthly/Quarterly
... A15: D14 | B15: 加密与稳定币流动性（主题） | C15: Theme Panel | D15: 1 | E15: 稳定币与链上流动性（低权重主题观察）。 | F15: Daily/Weekly

Sheet Indicators
A1: IndicatorCode | B1: DimensionID | C1: IndicatorName | D1: Units | E1: Frequency | F1: Source | G1: SourceURL | H1: Series/Code | I1: ScaleType | J1: Direction | K1: Best | L1: Worst | M1: WorstLow | N1: TargetLow | O1: TargetHigh | P1: WorstHigh | Q1: CapLow | R1: CapHigh | S1: WeightWithinDim | T1: Notes
A2: YC_10Y3M | B2: D01 | C2: 10Y-3M利差（bps） | D2: bps | E2: Daily | F2: FRED (H.15) | G2: https://fred.stlouisfed.org/series/DGS10 | H2: DGS10 & DGS3MO | I2: Linear | J2: HigherBetter | K2: 150 | L2: -200 | S2: 0.4 | T2: 在 Scores 表用(10Y-3M)输入；建议直接填利差值。
A3: SOFR | B3: D01 | C3: SOFR（%） | D3: % | E3: Daily | F3: NY Fed / FRED | G3: https://fred.stlouisfed.org/series/SOFR | H3: SOFR | I3: Linear | J3: LowerBetter | K3: 0.5 | L3: 7 | Q3: 0 | R3: 15 | S3: 0.25 | T3: 可替换为EFFR或短端实际利率。
A4: FED_ASSETS | B4: D01 | C4: 美联储总资产（$T） | D4: $T | E4: Weekly | F4: FRED (H.4.1) | G4: https://fred.stlouisfed.org/series/WALCL | H4: WALCL | I4: Linear | J4: LowerBetter | K4: 5 | L4: 9 | S4: 0.15 | T4: 用于衡量QE/QT方向；也可改为YoY变化。
A5: NET_LIQ_PROXY | B5: D01 | C5: 净流动性代理（自定义） | D5: index | E5: Weekly | F5: User Calc | G5: (填你的来源或模型) | H5: N/A | I5: Linear | J5: HigherBetter | K5: 1 | L5: -1 | S5: 0.2 | T5: 建议：Fed资产- TGA - RRP（需你定义并填值）。
A6: GDP_QOQ_SAAR | B6: D02 | C6: 实际GDP环比折年（%） | D6: % | E6: Quarterly | F6: BEA | G6: https://www.bea.gov/ | H6: GDP | I6: TargetBand | J6: TargetRange | M6: -2 | N6: 1.5 | O6: 3 | P6: 5 | S6: 0.3 | T6: 区间内更理想；衰退/过热都扣分。
A7: PMI_MAN | B7: D02 | C7: 制造业PMI | D7: index | E7: Monthly | F7: ISM/S&P | G7: (填你使用的PMI来源) | H7: PMI | I7: TargetBand | J7: TargetRange | M7: 45 | N7: 50 | O7: 55 | P7: 60 | S7: 0.25 | T7: >=50扩张；过热也可能引发通胀/政策收紧。
A8: CLAIMS_4WMA | B8: D02 | C8: 初请失业金四周均值 | D8: k | E8: Weekly | F8: FRED | G8: https://fred.stlouisfed.org/series/IC4WSA | H8: IC4WSA | I8: Linear | J8: LowerBetter | K8: 180 | L8: 400 | S8: 0.25 | T8: 越低越好。
A9: LEI | B9: D02 | C9: 领先指标（LEI）同比（%） | D9: % | E9: Monthly | F9: Conference Board | G9: https://www.conference-board.org/ | H9: LEI YoY | I9: Linear | J9: HigherBetter | K9: 5 | L9: -10 | S9: 0.2 | T9: 需要你接入LEI数据。
A10: CORE_CPI_YOY | B10: D03 | C10: 核心CPI同比（%） | D10: % | E10: Monthly | F10: BLS/FRED | G10: https://fred.stlouisfed.org/series/CPILFESL | H10: CPILFESL | I10: TargetBand | J10: TargetRange | M10: 0.5 | N10: 2 | O10: 2.7 | P10: 5 | S10: 0.35 | T10: 目标区间可按你的政策偏好调整。
A11: CORE_PCE_YOY | B11: D03 | C11: 核心PCE同比（%） | D11: % | E11: Monthly | F11: BEA/FRED | G11: https://fred.stlouisfed.org/series/PCEPILFE | H11: PCEPILFE | I11: TargetBand | J11: TargetRange | M11: 0.5 | N11: 1.8 | O11: 2.5 | P11: 4.5 | S11: 0.35 | T11: 更贴近美联储目标。
A12: BREAKEVEN_5Y5Y | B12: D03 | C12: 5Y5Y通胀预期（%） | D12: % | E12: Daily | F12: FRED | G12: https://fred.stlouisfed.org/series/T5YIFR | H12: T5YIFR | I12: TargetBand | J12: TargetRange | M12: 0.5 | N12: 2 | O12: 2.6 | P12: 3.5 | S12: 0.3 | T12: 也可用10Y BEI等。
A13: UNRATE | B13: D04 | C13: 失业率（%） | D13: % | E13: Monthly | F13: BLS/FRED | G13: https://fred.stlouisfed.org/series/UNRATE | H13: UNRATE | I13: TargetBand | J13: TargetRange | M13: 2.5 | N13: 3.5 | O13: 4.5 | P13: 7 | S13: 0.35 | T13: 过低可能偏热；过高是衰退信号。
A14: WAGE_GROWTH | B14: D04 | C14: 平均时薪同比（%） | D14: % | E14: Monthly | F14: BLS/FRED | G14: https://fred.stlouisfed.org/series/CES0500000003 | H14: CES0500000003 | I14: TargetBand | J14: TargetRange | M14: 0.5 | N14: 3 | O14: 4 | P14: 6 | S14: 0.25 | T14: 工资过高可能推升服务通胀。
A15: CC_DELINQ | B15: D04 | C15: 信用卡拖欠率（%） | D15: % | E15: Quarterly | F15: FRED | G15: https://fred.stlouisfed.org/series/DRCCLACBS | H15: DRCCLACBS | I15: Linear | J15: LowerBetter | K15: 1.5 | L15: 5 | S15: 0.25 | T15: 也可加车贷/学生贷。
A16: REAL_DISP_INC | B16: D04 | C16: 实际可支配收入同比（%） | D16: % | E16: Monthly | F16: BEA/FRED | G16: https://fred.stlouisfed.org/series/DSPIC96 | H16: DSPIC96 | I16: Linear | J16: HigherBetter | K16: 4 | L16: -4 | S16: 0.15 | T16: 用YoY变化需你在 Inputs 填值。
A17: SPX_FWD_PE | B17: D05 | C17: 标普500 Forward P/E（x） | D17: x | E17: Weekly | F17: FactSet/S&P | G17: (填你的数据源) | H17: FWD PE | I17: Linear | J17: LowerBetter | K17: 14 | L17: 28 | S17: 0.3 | T17: 若你无FactSet，可用公开估值替代。
A18: EPS_REV_BREADTH | B18: D05 | C18: EPS修正广度（上调-下调，%） | D18: % | E18: Weekly | F18: IBES/FactSet | G18: (填你的数据源) | H18: EPS rev | I18: Linear | J18: HigherBetter | K18: 30 | L18: -30 | S18: 0.35 | T18: 无数据则先留空。
A19: HY_OAS | B19: D05 | C19: 高收益信用利差OAS（bps） | D19: bps | E19: Daily | F19: FRED | G19: https://fred.stlouisfed.org/series/BAMLH0A0HYM2 | H19: BAMLH0A0HYM2 | I19: Linear | J19: LowerBetter | K19: 250 | L19: 900 | S19: 0.35 | T19: 信用压力核心指标。
A20: MORTGAGE_30Y | B20: D06 | C20: 30年按揭利率（%） | D20: % | E20: Weekly | F20: Freddie Mac | G20: https://www.freddiemac.com/pmms | H20: PMMS | I20: Linear | J20: LowerBetter | K20: 3 | L20: 8.5 | S20: 0.35 | T20: 用PMMS周度。
A21: EXIST_HOME_SALES | B21: D06 | C21: 成屋销售折年（百万套） | D21: M | E21: Monthly | F21: NAR | G21: https://www.nar.realtor/ | H21: EHS | I21: Linear | J21: HigherBetter | K21: 6 | L21: 3 | S21: 0.35 | T21: 反映交易活跃度。
A22: HOUSING_STARTS | B22: D06 | C22: 新屋开工（百万套） | D22: M | E22: Monthly | F22: Census/FRED | G22: https://fred.stlouisfed.org/series/HOUST | H22: HOUST | I22: Linear | J22: HigherBetter | K22: 1.8 | L22: 0.9 | S22: 0.3 | T22: 更前瞻。
A23: VIX | B23: D07 | C23: VIX | D23: index | E23: Daily | F23: CBOE/FRED | G23: https://fred.stlouisfed.org/series/VIXCLS | H23: VIXCLS | I23: Linear | J23: LowerBetter | K23: 12 | L23: 45 | S23: 0.4
A24: MOVE | B24: D07 | C24: MOVE | D24: index | E24: Daily | F24: ICE | G24: (填你使用的MOVE来源) | H24: MOVE | I24: Linear | J24: LowerBetter | K24: 60 | L24: 160 | S24: 0.35 | T24: 可用公开报价源；确保口径一致。
A25: SPX_DD_3M | B25: D07 | C25: 标普500近3个月最大回撤（%） | D25: % | E25: Daily | F25: User Calc | G25: (填你的来源) | H25: N/A | I25: Linear | J25: LowerBetter | K25: 0 | L25: 20 | S25: 0.25 | T25: 可选，用于风险状态。
A26: DXY | B26: D08 | C26: 美元指数DXY | D26: index | E26: Daily | F26: ICE/公开行情 | G26: (填你来源) | H26: DXY | I26: TargetBand | J26: TargetRange | M26: 85 | N26: 92 | O26: 102 | P26: 112 | S26: 0.35 | T26: 美元过强/过弱都可能带来问题。
A27: US_JP_10Y_SPREAD | B27: D08 | C27: 美日10Y利差（bps） | D27: bps | E27: Daily | F27: FRED/BOJ | G27: (填你来源) | H27: N/A | I27: Linear | J27: HigherBetter | K27: 250 | L27: 0 | S27: 0.35 | T27: 利差过大=套息/汇率波动风险上升，方向可按策略调整。
A28: CAPITAL_FLOWS | B28: D08 | C28: 海外净买入美国资产（自定义） | D28: $B | E28: Monthly | F28: Treasury TIC/EPFR | G28: (填你的来源) | H28: TIC/EPFR | I28: Linear | J28: HigherBetter | K28: 80 | L28: -80 | S28: 0.3 | T28: 无数据可暂留空。
A29: DEFICIT_GDP | B29: D09 | C29: 财政赤字/GDP（%） | D29: % | E29: Annual/Quarterly | F29: CBO | G29: https://www.cbo.gov/publication/62105 | H29: CBO baseline | I29: Linear | J29: LowerBetter | K29: 2 | L29: 10 | S29: 0.45 | T29: 越低越可持续。
A30: DEBT_GDP | B30: D09 | C30: 债务/GDP（%） | D30: % | E30: Annual | F30: CBO | G30: https://www.cbo.gov/publication/62105 | H30: CBO baseline | I30: Linear | J30: LowerBetter | K30: 60 | L30: 140 | S30: 0.3
A31: INT_REV | B31: D09 | C31: 利息支出/财政收入（%） | D31: % | E31: Annual | F31: Treasury/CBO | G31: (填你的来源) | H31: N/A | I31: Linear | J31: LowerBetter | K31: 8 | L31: 25 | S31: 0.25 | T31: 强烈建议加入，体现财政挤出。
A32: FCI | B32: D10 | C32: 金融条件指数（FCI） | D32: index | E32: Weekly | F32: GS/Chicago Fed | G32: (填你来源) | H32: FCI | I32: Linear | J32: LowerBetter | K32: -1 | L32: 1.5 | S32: 0.4 | T32: FCI越高越紧。
A33: BANK_LENDING | B33: D10 | C33: 银行信贷增速（% YoY） | D33: % | E33: Weekly/Monthly | F33: Fed H.8 | G33: (填你来源) | H33: H.8 | I33: TargetBand | J33: TargetRange | M33: -5 | N33: 2 | O33: 8 | P33: 15 | S33: 0.35 | T33: 过低=信用收缩。
A34: TED_SPREAD | B34: D10 | C34: TED利差（bps） | D34: bps | E34: Daily | F34: FRED | G34: https://fred.stlouisfed.org/series/TEDRATE | H34: TEDRATE | I34: Linear | J34: LowerBetter | K34: 20 | L34: 150 | S34: 0.25 | T34: 资金面压力信号。
A35: WTI | B35: D11 | C35: WTI原油（$/桶） | D35: $/bbl | E35: Daily | F35: NYMEX/公开行情 | G35: (填你来源) | H35: WTI | I35: TargetBand | J35: TargetRange | M35: 30 | N35: 55 | O35: 85 | P35: 120 | S35: 0.4 | T35: 过高推通胀；过低或反映需求弱。
A36: CRB | B36: D11 | C36: 大宗商品指数（CRB）同比（%） | D36: % | E36: Weekly | F36: Refinitiv/公开 | G36: (填你来源) | H36: CRB | I36: TargetBand | J36: TargetRange | M36: -20 | N36: -5 | O36: 10 | P36: 30 | S36: 0.3 | T36: 需你填YoY变化。
A37: GPR | B37: D11 | C37: 地缘政治风险指数（GPR） | D37: index | E37: Monthly | F37: Caldara & Iacoviello | G37: https://www.matteoiacoviello.com/gpr.htm | H37: GPR | I37: Linear | J37: LowerBetter | K37: 80 | L37: 250 | S37: 0.3 | T37: 务必填具体数值，不要只写“低位”。
A38: CB_CONS_CONF | B38: D12 | C38: 消费者信心指数 | D38: index | E38: Monthly | F38: Conference Board | G38: https://www.conference-board.org/ | H38: Consumer Confidence | I38: Linear | J38: HigherBetter | K38: 120 | L38: 60 | S38: 0.45
A39: CEO_CONF | B39: D12 | C39: CEO Confidence | D39: index | E39: Quarterly | F39: Conference Board | G39: https://www.conference-board.org/topics/CEO-Confidence/ | H39: CEO Confidence | I39: Linear | J39: HigherBetter | K39: 70 | L39: 35 | S39: 0.35 | T39: >50偏正面。
A40: EPU | B40: D12 | C40: 经济政策不确定性（EPU） | D40: index | E40: Monthly | F40: policyuncertainty.com | G40: https://www.policyuncertainty.com/ | H40: EPU | I40: Linear | J40: LowerBetter | K40: 80 | L40: 300 | S40: 0.2 | T40: 不确定性越高越差。
...

Sheet Inputs
A1: Inputs（填最新值）
A2: AsOf（模型更新日期） | B2: 2026-10-22
A4: 蓝色单元格为输入。IndicatorCode 建议用下拉选择，避免拼写错误。
A6: IndicatorCode | B6: LatestValue | C6: ValueDate | D6: SourceDate | E6: Notes
A7: YC_10Y3M | B7: 50 | C7: 2026-03-11 | D7: 2026-03-13 | E7: 样例值，接近 2026-02-26 官方收益率差（10Y≈4.02%, 3M≈3.68%）。
A8: SOFR | B8: 3.64 | C8: 2026-03-11 | D8: 2026-03-13 | E8: 演示样例值；请用你自己的权威数据源替换。
A9: FED_ASSETS | B9: 6.6463 | C9: 2026-03-11 | D9: 2026-03-13 | E9: 演示样例值；请用你自己的权威数据源替换。
A10: NET_LIQ_PROXY | B10: -831.5398 | C10: 2026-03-12 | D10: 2026-03-13 | E10: 演示样例值；请用你自己的权威数据源替换。
A11: GDP_QOQ_SAAR | B11: 1.4 | C11: 2025-10-01 | D11: 2026-03-13 | E11: 样例值，对应 BEA 2025Q4 实际GDP环比折年 1.4%。
A12: PMI_MAN | B12: 52.5 | C12: 2026-03-01 | D12: 2026-03-01 | E12: 演示样例值；请用你自己的权威数据源替换。
A13: CLAIMS_4WMA | B13: 212000 | C13: 2026-03-07 | D13: 2026-03-13 | E13: 演示样例值；请用你自己的权威数据源替换。
A14: LEI | B14: -0.8 | C14: 2026-03-01 | D14: 2026-03-01 | E14: 演示样例值；请用你自己的权威数据源替换。
A15: CORE_CPI_YOY | B15: 2.7335 | C15: 2026-02-01 | D15: 2026-03-13 | E15: 样例值，对应 2026年1月核心CPI同比 2.5%。
A16: CORE_PCE_YOY | B16: 2.9969 | C16: 2025-12-01 | D16: 2026-03-13 | E16: 演示样例值；请用你自己的权威数据源替换。
A17: BREAKEVEN_5Y5Y | B17: 2.13 | C17: 2026-03-12 | D17: 2026-03-13 | E17: 演示样例值；请用你自己的权威数据源替换。
A18: UNRATE | B18: 4.4 | C18: 2026-02-01 | D18: 2026-03-13 | E18: 样例值，对应 2026年1月失业率 4.3%。
... A51: STABLECOIN_DOM | B51: 305.5167 | C51: 2026-10-22 | D51: 2026-10-22 | E51: 演示样例值；请用你自己的权威数据源替换。

Sheet Scores
A1: Scores（自动计算）
A3: 指标分数
A5: IndicatorCode | B5: IndicatorName | C5: DimensionID | D5: LatestValue | E5: CappedValue | F5: Score(0-100) | G5: WeightWithinDim | H5: WeightedScore | I5: SourceURL
A6: YC_10Y3M | B6: =INDEX(Indicators!$C$2:$C$46, MATCH($A6, Indicators!$A$2:$A$46, 0)) | C6: =INDEX(Indicators!$B$2:$B$46, MATCH($A6, Indicators!$A$2:$A$46, 0)) | D6: =IFERROR(INDEX(Inputs!$B$7:$B$51, MATCH($A6, Inputs!$A$7:$A$51, 0)),"") | E6: =IF($D6="","",IF(AND(INDEX(Indicators!$Q$2:$Q$46, MATCH($A6, Indicators!$A$2:$A$46, 0))="",INDEX(Indicators!$R$2:$R$46, MATCH($A6, Indicators!$A$2:$A$46, 0))=""),$D6,IF(INDEX(Indicators!$Q$2:$Q$46, MATCH($A6, Indicators!$A$2:$A$46, 0))="",MIN($D6,INDEX(Indicators!$R$2:$R$46, MATCH($A6, Indicators!$A$2:$A$46, 0))),IF(INDEX(Indicators!$R$2:$R$46, MATCH($A6, Indicators!$A$2:$A$46, 0))="",MAX($D6,INDEX(Indicators!$Q$2:$Q$46, MATCH($A6, Indicators!$A$2:$A$46, 0))),MIN(MAX($D6,INDEX(Indicators!$Q$2:$Q$46, MATCH($A6, Indicators!$A$2:$A$46, 0))),INDEX(Indicators!$R$2:$R$46, MATCH($A6, Indicators!$A$2:$A$46, 0))))))) | F6: =IF($E6="","",IF(INDEX(Indicators!$I$2:$I$46, MATCH($A6, Indicators!$A$2:$A$46, 0))="TargetBand",IF(AND($E6>=INDEX(Indicators!$N$2:$N$46, MATCH($A6, Indicators!$A$2:$A$46, 0)),$E6<=INDEX(Indicators!$O$2:$O$46, MATCH($A6, Indicators!$A$2:$A$46, 0))),100,IF($E6<INDEX(Indicators!$N$2:$N$46, MATCH($A6, Indicators!$A$2:$A$46, 0)),MAX(0,MIN(100,($E6-INDEX(Indicators!$M$2:$M$46, MATCH($A6, Indicators!$A$2:$A$46, 0)))/(INDEX(Indicators!$N$2:$N$46, MATCH($A6, Indicators!$A$2:$A$46, 0))-INDEX(Indicators!$M$2:$M$46, MATCH($A6, Indicators!$A$2:$A$46, 0)))*100)),MAX(0,MIN(100,(INDEX(Indicators!$P$2:$P$46, MATCH($A6, Indicators!$A$2:$A$46, 0))-$E6)/(INDEX(Indicators!$P$2:$P$46, MATCH($A6, Indicators!$A$2:$A$46, 0))-INDEX(Indicators!$O$2:$O$46, MATCH($A6, Indicators!$A$2:$A$46, 0)))*100)))),IF(INDEX(Indicators!$J$2:$J$46, MATCH($A6, Indicators!$A$2:$A$46, 0))="HigherBetter",MAX(0,MIN(100,($E6-INDEX(Indicators!$L$2:$L$46, MATCH($A6, Indicators!$A$2:$A$46, 0)))/(INDEX(Indicators!$K$2:$K$46, MATCH($A6, Indicators!$A$2:$A$46, 0))-INDEX(Indicators!$L$2:$L$46, MATCH($A6, Indicators!$A$2:$A$46, 0)))*100)),IF(INDEX(Indicators!$J$2:$J$46, MATCH($A6, Indicators!$A$2:$A$46, 0))="LowerBetter",MAX(0,MIN(100,(INDEX(Indicators!$L$2:$L$46, MATCH($A6, Indicators!$A$2:$A$46, 0))-$E6)/(INDEX(Indicators!$L$2:$L$46, MATCH($A6, Indicators!$A$2:$A$46, 0))-INDEX(Indicators!$K$2:$K$46, MATCH($A6, Indicators!$A$2:$A$46, 0)))*100)),"")))) | G6: =IFERROR(INDEX(Indicators!$S$2:$S$46, MATCH($A6, Indicators!$A$2:$A$46, 0)),"") | H6: =IF($F6="","",$F6*$G6) | I6: =IFERROR(INDEX(Indicators!$G$2:$G$46, MATCH($A6, Indicators!$A$2:$A$46, 0)),"")
A7: SOFR | B7: =INDEX(Indicators!$C$2:$C$46, MATCH($A7, Indicators!$A$2:$A$46, 0)) | C7: =INDEX(Indicators!$B$2:$B$46, MATCH($A7, Indicators!$A$2:$A$46, 0)) | D7: =IFERROR(INDEX(Inputs!$B$7:$B$51, MATCH($A7, Inputs!$A$7:$A$51, 0)),"") | E7: =IF($D7="","",IF(AND(INDEX(Indicators!$Q$2:$Q$46, MATCH($A7, Indicators!$A$2:$A$46, 0))="",INDEX(Indicators!$R$2:$R$46, MATCH($A7, Indicators!$A$2:$A$46, 0))=""),$D7,IF(INDEX(Indicators!$Q$2:$Q$46, MATCH($A7, Indicators!$A$2:$A$46, 0))="",MIN($D7,INDEX(Indicators!$R$2:$R$46, MATCH($A7, Indicators!$A$2:$A$46, 0))),IF(INDEX(Indicators!$R$2:$R$46, MATCH($A7, Indicators!$A$2:$A$46, 0))="",MAX($D7,INDEX(Indicators!$Q$2:$Q$46, MATCH($A7, Indicators!$A$2:$A$46, 0))),MIN(MAX($D7,INDEX(Indicators!$Q$2:$Q$46, MATCH($A7, Indicators!$A$2:$A$46, 0))),INDEX(Indicators!$R$2:$R$46, MATCH($A7, Indicators!$A$2:$A$46, 0))))))) | F7: =IF($E7="","",IF(INDEX(Indicators!$I$2:$I$46, MATCH($A7, Indicators!$A$2:$A$46, 0))="TargetBand",IF(AND($E7>=INDEX(Indicators!$N$2:$N$46, MATCH($A7, Indicators!$A$2:$A$46, 0)),$E7<=INDEX(Indicators!$O$2:$O$46, MATCH($A7, Indicators!$A$2:$A$46, 0))),100,IF($E7<INDEX(Indicators!$N$2:$N$46, MATCH($A7, Indicators!$A$2:$A$46, 0)),MAX(0,MIN(100,($E7-INDEX(Indicators!$M$2:$M$46, MATCH($A7, Indicators!$A$2:$A$46, 0)))/(INDEX(Indicators!$N$2:$N$46, MATCH($A7, Indicators!$A$2:$A$46, 0))-INDEX(Indicators!$M$2:$M$46, MATCH($A7, Indicators!$A$2:$A$46, 0)))*100)),MAX(0,MIN(100,(INDEX(Indicators!$P$2:$P$46, MATCH($A7, Indicators!$A$2:$A$46, 0))-$E7)/(INDEX(Indicators!$P$2:$P$46, MATCH($A7, Indicators!$A$2:$A$46, 0))-INDEX(Indicators!$O$2:$O$46, MATCH($A7, Indicators!$A$2:$A$46, 0)))*100)))),IF(INDEX(Indicators!$J$2:$J$46, MATCH($A7, Indicators!$A$2:$A$46, 0))="HigherBetter",MAX(0,MIN(100,($E7-INDEX(Indicators!$L$2:$L$46, MATCH($A7, Indicators!$A$2:$A$46, 0)))/(INDEX(Indicators!$K$2:$K$46, MATCH($A7, Indicators!$A$2:$A$46, 0))-INDEX(Indicators!$L$2:$L$46, MATCH($A7, Indicators!$A$2:$A$46, 0)))*100)),IF(INDEX(Indicators!$J$2:$J$46, MATCH($A7, Indicators!$A$2:$A$46, 0))="LowerBetter",MAX(0,MIN(100,(INDEX(Indicators!$L$2:$L$46, MATCH($A7, Indicators!$A$2:$A$46, 0))-$E7)/(INDEX(Indicators!$L$2:$L$46, MATCH($A7, Indicators!$A$2:$A$46, 0))-INDEX(Indicators!$K$2:$K$46, MATCH($A7, Indicators!$A$2:$A$46, 0)))*100)),"")))) | G7: =IFERROR(INDEX(Indicators!$S$2:$S$46, MATCH($A7, Indicators!$A$2:$A$46, 0)),"") | H7: =IF($F7="","",$F7*$G7) | I7: =IFERROR(INDEX(Indicators!$G$2:$G$46, MATCH($A7, Indicators!$A$2:$A$46, 0)),"")
A8: FED_ASSETS | B8: =INDEX(Indicators!$C$2:$C$46, MATCH($A8, Indicators!$A$2:$A$46, 0)) | C8: =INDEX(Indicators!$B$2:$B$46, MATCH($A8, Indicators!$A$2:$A$46, 0)) | D8: =IFERROR(INDEX(Inputs!$B$7:$B$51, MATCH($A8, Inputs!$A$7:$A$51, 0)),"") | E8: =IF($D8="","",IF(AND(INDEX(Indicators!$Q$2:$Q$46, MATCH($A8, Indicators!$A$2:$A$46, 0))="",INDEX(Indicators!$R$2:$R$46, MATCH($A8, Indicators!$A$2:$A$46, 0))=""),$D8,IF(INDEX(Indicators!$Q$2:$Q$46, MATCH($A8, Indicators!$A$2:$A$46, 0))="",MIN($D8,INDEX(Indicators!$R$2:$R$46, MATCH($A8, Indicators!$A$2:$A$46, 0))),IF(INDEX(Indicators!$R$2:$R$46, MATCH($A8, Indicators!$A$2:$A$46, 0))="",MAX($D8,INDEX(Indicators!$Q$2:$Q$46, MATCH($A8, Indicators!$A$2:$A$46, 0))),MIN(MAX($D8,INDEX(Indicators!$Q$2:$Q$46, MATCH($A8, Indicators!$A$2:$A$46, 0))),INDEX(Indicators!$R$2:$R$46, MATCH($A8, Indicators!$A$2:$A$46, 0))))))) | F8: =IF($E8="","",IF(INDEX(Indicators!$I$2:$I$46, MATCH($A8, Indicators!$A$2:$A$46, 0))="TargetBand",IF(AND($E8>=INDEX(Indicators!$N$2:$N$46, MATCH($A8, Indicators!$A$2:$A$46, 0)),$E8<=INDEX(Indicators!$O$2:$O$46, MATCH($A8, Indicators!$A$2:$A$46, 0))),100,IF($E8<INDEX(Indicators!$N$2:$N$46, MATCH($A8, Indicators!$A$2:$A$46, 0)),MAX(0,MIN(100,($E8-INDEX(Indicators!$M$2:$M$46, MATCH($A8, Indicators!$A$2:$A$46, 0)))/(INDEX(Indicators!$N$2:$N$46, MATCH($A8, Indicators!$A$2:$A$46, 0))-INDEX(Indicators!$M$2:$M$46, MATCH($A8, Indicators!$A$2:$A$46, 0)))*100)),MAX(0,MIN(100,(INDEX(Indicators!$P$2:$P$46, MATCH($A8, Indicators!$A$2:$A$46, 0))-$E8)/(INDEX(Indicators!$P$2:$P$46, MATCH($A8, Indicators!$A$2:$A$46, 0))-INDEX(Indicators!$O$2:$O$46, MATCH($A8, Indicators!$A$2:$A$46, 0)))*100)))),IF(INDEX(Indicators!$J$2:$J$46, MATCH($A8, Indicators!$A$2:$A$46, 0))="HigherBetter",MAX(0,MIN(100,($E8-INDEX(Indicators!$L$2:$L$46, MATCH($A8, Indicators!$A$2:$A$46, 0)))/(INDEX(Indicators!$K$2:$K$46, MATCH($A8, Indicators!$A$2:$A$46, 0))-INDEX(Indicators!$L$2:$L$46, MATCH($A8, Indicators!$A$2:$A$46, 0)))*100)),IF(INDEX(Indicators!$J$2:$J$46, MATCH($A8, Indicators!$A$2:$A$46, 0))="LowerBetter",MAX(0,MIN(100,(INDEX(Indicators!$L$2:$L$46, MATCH($A8, Indicators!$A$2:$A$46, 0))-$E8)/(INDEX(Indicators!$L$2:$L$46, MATCH($A8, Indicators!$A$2:$A$46, 0))-INDEX(Indicators!$K$2:$K$46, MATCH($A8, Indicators!$A$2:$A$46, 0)))*100)),"")))) | G8: =IFERROR(INDEX(Indicators!$S$2:$S$46, MATCH($A8, Indicators!$A$2:$A$46, 0)),"") | H8: =IF($F8="","",$F8*$G8) | I8: =IFERROR(INDEX(Indicators!$G$2:$G$46, MATCH($A8, Indicators!$A$2:$A$46, 0)),"")
A9: NET_LIQ_PROXY | B9: =INDEX(Indicators!$C$2:$C$46, MATCH($A9, Indicators!$A$2:$A$46, 0)) | C9: =INDEX(Indicators!$B$2:$B$46, MATCH($A9, Indicators!$A$2:$A$46, 0)) | D9: =IFERROR(INDEX(Inputs!$B$7:$B$51, MATCH($A9, Inputs!$A$7:$A$51, 0)),"") | E9: =IF($D9="","",IF(AND(INDEX(Indicators!$Q$2:$Q$46, MATCH($A9, Indicators!$A$2:$A$46, 0))="",INDEX(Indicators!$R$2:$R$46, MATCH($A9, Indicators!$A$2:$A$46, 0))=""),$D9,IF(INDEX(Indicators!$Q$2:$Q$46, MATCH($A9, Indicators!$A$2:$A$46, 0))="",MIN($D9,INDEX(Indicators!$R$2:$R$46, MATCH($A9, Indicators!$A$2:$A$46, 0))),IF(INDEX(Indicators!$R$2:$R$46, MATCH($A9, Indicators!$A$2:$A$46, 0))="",MAX($D9,INDEX(Indicators!$Q$2:$Q$46, MATCH($A9, Indicators!$A$2:$A$46, 0))),MIN(MAX($D9,INDEX(Indicators!$Q$2:$Q$46, MATCH($A9, Indicators!$A$2:$A$46, 0))),INDEX(Indicators!$R$2:$R$46, MATCH($A9, Indicators!$A$2:$A$46, 0))))))) | F9: =IF($E9="","",IF(INDEX(Indicators!$I$2:$I$46, MATCH($A9, Indicators!$A$2:$A$46, 0))="TargetBand",IF(AND($E9>=INDEX(Indicators!$N$2:$N$46, MATCH($A9, Indicators!$A$2:$A$46, 0)),$E9<=INDEX(Indicators!$O$2:$O$46, MATCH($A9, Indicators!$A$2:$A$46, 0))),100,IF($E9<INDEX(Indicators!$N$2:$N$46, MATCH($A9, Indicators!$A$2:$A$46, 0)),MAX(0,MIN(100,($E9-INDEX(Indicators!$M$2:$M$46, MATCH($A9, Indicators!$A$2:$A$46, 0)))/(INDEX(Indicators!$N$2:$N$46, MATCH($A9, Indicators!$A$2:$A$46, 0))-INDEX(Indicators!$M$2:$M$46, MATCH($A9, Indicators!$A$2:$A$46, 0)))*100)),MAX(0,MIN(100,(INDEX(Indicators!$P$2:$P$46, MATCH($A9, Indicators!$A$2:$A$46, 0))-$E9)/(INDEX(Indicators!$P$2:$P$46, MATCH($A9, Indicators!$A$2:$A$46, 0))-INDEX(Indicators!$O$2:$O$46, MATCH($A9, Indicators!$A$2:$A$46, 0)))*100)))),IF(INDEX(Indicators!$J$2:$J$46, MATCH($A9, Indicators!$A$2:$A$46, 0))="HigherBetter",MAX(0,MIN(100,($E9-INDEX(Indicators!$L$2:$L$46, MATCH($A9, Indicators!$A$2:$A$46, 0)))/(INDEX(Indicators!$K$2:$K$46, MATCH($A9, Indicators!$A$2:$A$46, 0))-INDEX(Indicators!$L$2:$L$46, MATCH($A9, Indicators!$A$2:$A$46, 0)))*100)),IF(INDEX(Indicators!$J$2:$J$46, MATCH($A9, Indicators!$A$2:$A$46, 0))="LowerBetter",MAX(0,MIN(100,(INDEX(Indicators!$L$2:$L$46, MATCH($A9, Indicators!$A$2:$A$46, 0))-$E9)/(INDEX(Indicators!$L$2:$L$46, MATCH($A9, Indicators!$A$2:$A$46, 0))-INDEX(Indicators!$K$2:$K$46, MATCH($A9, Indicators!$A$2:$A$46, 0)))*100)),"")))) | G9: =IFERROR(INDEX(Indicators!$S$2:$S$46, MATCH($A9, Indicators!$A$2:$A$46, 0)),"") | H9: =IF($F9="","",$F9*$G9) | I9: =IFERROR(INDEX(Indicators!$G$2:$G$46, MATCH($A9, Indicators!$A$2:$A$46, 0)),"")
A10: GDP_QOQ_SAAR | B10: =INDEX(Indicators!$C$2:$C$46, MATCH($A10, Indicators!$A$2:$A$46, 0)) | C10: =INDEX(Indicators!$B$2:$B$46, MATCH($A10, Indicators!$A$2:$A$46, 0)) | D10: =IFERROR(INDEX(Inputs!$B$7:$B$51, MATCH($A10, Inputs!$A$7:$A$51, 0)),"") | E10: =IF($D10="","",IF(AND(INDEX(Indicators!$Q$2:$Q$46, MATCH($A10, Indicators!$A$2:$A$46, 0))="",INDEX(Indicators!$R$2:$R$46, MATCH($A10, Indicators!$A$2:$A$46, 0))=""),$D10,IF(INDEX(Indicators!$Q$2:$Q$46, MATCH($A10, Indicators!$A$2:$A$46, 0))="",MIN($D10,INDEX(Indicators!$R$2:$R$46, MATCH($A10, Indicators!$A$2:$A$46, 0))),IF(INDEX(Indicators!$R$2:$R$46, MATCH($A10, Indicators!$A$2:$A$46, 0))="",MAX($D10,INDEX(Indicators!$Q$2:$Q$46, MATCH($A10, Indicators!$A$2:$A$46, 0))),MIN(MAX($D10,INDEX(Indicators!$Q$2:$Q$46, MATCH($A10, Indicators!$A$2:$A$46, 0))),INDEX(Indicators!$R$2:$R$46, MATCH($A10, Indicators!$A$2:$A$46, 0))))))) | F10: =IF($E10="","",IF(INDEX(Indicators!$I$2:$I$46, MATCH($A10, Indicators!$A$2:$A$46, 0))="TargetBand",IF(AND($E10>=INDEX(Indicators!$N$2:$N$46, MATCH($A10, Indicators!$A$2:$A$46, 0)),$E10<=INDEX(Indicators!$O$2:$O$46, MATCH($A10, Indicators!$A$2:$A$46, 0))),100,IF($E10<INDEX(Indicators!$N$2:$N$46, MATCH($A10, Indicators!$A$2:$A$46, 0)),MAX(0,MIN(100,($E10-INDEX(Indicators!$M$2:$M$46, MATCH($A10, Indicators!$A$2:$A$46, 0)))/(INDEX(Indicators!$N$2:$N$46, MATCH($A10, Indicators!$A$2:$A$46, 0))-INDEX(Indicators!$M$2:$M$46, MATCH($A10, Indicators!$A$2:$A$46, 0)))*100)),MAX(0,MIN(100,(INDEX(Indicators!$P$2:$P$46, MATCH($A10, Indicators!$A$2:$A$46, 0))-$E10)/(INDEX(Indicators!$P$2:$P$46, MATCH($A10, Indicators!$A$2:$A$46, 0))-INDEX(Indicators!$O$2:$O$46, MATCH($A10, Indicators!$A$2:$A$46, 0)))*100)))),IF(INDEX(Indicators!$J$2:$J$46, MATCH($A10, Indicators!$A$2:$A$46, 0))="HigherBetter",MAX(0,MIN(100,($E10-INDEX(Indicators!$L$2:$L$46, MATCH($A10, Indicators!$A$2:$A$46, 0)))/(INDEX(Indicators!$K$2:$K$46, MATCH($A10, Indicators!$A$2:$A$46, 0))-INDEX(Indicators!$L$2:$L$46, MATCH($A10, Indicators!$A$2:$A$46, 0)))*100)),IF(INDEX(Indicators!$J$2:$J$46, MATCH($A10, Indicators!$A$2:$A$46, 0))="LowerBetter",MAX(0,MIN(100,(INDEX(Indicators!$L$2:$L$46, MATCH($A10, Indicators!$A$2:$A$46, 0))-$E10)/(INDEX(Indicators!$L$2:$L$46, MATCH($A10, Indicators!$A$2:$A$46, 0))-INDEX(Indicators!$K$2:$K$46, MATCH($A10, Indicators!$A$2:$A$46, 0)))*100)),"")))) | G10: =IFERROR(INDEX(Indicators!$S$2:$S$46, MATCH($A10, Indicators!$A$2:$A$46, 0)),"") | H10: =IF($F10="","",$F10*$G10) | I10: =IFERROR(INDEX(Indicators!$G$2:$G$46, MATCH($A10, Indicators!$A$2:$A$46, 0)),"")
A11: PMI_MAN | B11: =INDEX(Indicators!$C$2:$C$46, MATCH($A11, Indicators!$A$2:$A$46, 0)) | C11: =INDEX(Indicators!$B$2:$B$46, MATCH($A11, Indicators!$A$2:$A$46, 0)) | D11: =IFERROR(INDEX(Inputs!$B$7:$B$51, MATCH($A11, Inputs!$A$7:$A$51, 0)),"") | E11: =IF($D11="","",IF(AND(INDEX(Indicators!$Q$2:$Q$46, MATCH($A11, Indicators!$A$2:$A$46, 0))="",INDEX(Indicators!$R$2:$R$46, MATCH($A11, Indicators!$A$2:$A$46, 0))=""),$D11,IF(INDEX(Indicators!$Q$2:$Q$46, MATCH($A11, Indicators!$A$2:$A$46, 0))="",MIN($D11,INDEX(Indicators!$R$2:$R$46, MATCH($A11, Indicators!$A$2:$A$46, 0))),IF(INDEX(Indicators!$R$2:$R$46, MATCH($A11, Indicators!$A$2:$A$46, 0))="",MAX($D11,INDEX(Indicators!$Q$2:$Q$46, MATCH($A11, Indicators!$A$2:$A$46, 0))),MIN(MAX($D11,INDEX(Indicators!$Q$2:$Q$46, MATCH($A11, Indicators!$A$2:$A$46, 0))),INDEX(Indicators!$R$2:$R$46, MATCH($A11, Indicators!$A$2:$A$46, 0))))))) | F11: =IF($E11="","",IF(INDEX(Indicators!$I$2:$I$46, MATCH($A11, Indicators!$A$2:$A$46, 0))="TargetBand",IF(AND($E11>=INDEX(Indicators!$N$2:$N$46, MATCH($A11, Indicators!$A$2:$A$46, 0)),$E11<=INDEX(Indicators!$O$2:$O$46, MATCH($A11, Indicators!$A$2:$A$46, 0))),100,IF($E11<INDEX(Indicators!$N$2:$N$46, MATCH($A11, Indicators!$A$2:$A$46, 0)),MAX(0,MIN(100,($E11-INDEX(Indicators!$M$2:$M$46, MATCH($A11, Indicators!$A$2:$A$46, 0)))/(INDEX(Indicators!$N$2:$N$46, MATCH($A11, Indicators!$A$2:$A$46, 0))-INDEX(Indicators!$M$2:$M$46, MATCH($A11, Indicators!$A$2:$A$46, 0)))*100)),MAX(0,MIN(100,(INDEX(Indicators!$P$2:$P$46, MATCH($A11, Indicators!$A$2:$A$46, 0))-$E11)/(INDEX(Indicators!$P$2:$P$46, MATCH($A11, Indicators!$A$2:$A$46, 0))-INDEX(Indicators!$O$2:$O$46, MATCH($A11, Indicators!$A$2:$A$46, 0)))*100)))),IF(INDEX(Indicators!$J$2:$J$46, MATCH($A11, Indicators!$A$2:$A$46, 0))="HigherBetter",MAX(0,MIN(100,($E11-INDEX(Indicators!$L$2:$L$46, MATCH($A11, Indicators!$A$2:$A$46, 0)))/(INDEX(Indicators!$K$2:$K$46, MATCH($A11, Indicators!$A$2:$A$46, 0))-INDEX(Indicators!$L$2:$L$46, MATCH($A11, Indicators!$A$2:$A$46, 0)))*100)),IF(INDEX(Indicators!$J$2:$J$46, MATCH($A11, Indicators!$A$2:$A$46, 0))="LowerBetter",MAX(0,MIN(100,(INDEX(Indicators!$L$2:$L$46, MATCH($A11, Indicators!$A$2:$A$46, 0))-$E11)/(INDEX(Indicators!$L$2:$L$46, MATCH($A11, Indicators!$A$2:$A$46, 0))-INDEX(Indicators!$K$2:$K$46, MATCH($A11, Indicators!$A$2:$A$46, 0)))*100)),"")))) | G11: =IFERROR(INDEX(Indicators!$S$2:$S$46, MATCH($A11, Indicators!$A$2:$A$46, 0)),"") | H11: =IF($F11="","",$F11*$G11) | I11: =IFERROR(INDEX(Indicators!$G$2:$G$46, MATCH($A11, Indicators!$A$2:$A$46, 0)),"")
A12: CLAIMS_4WMA | B12: =INDEX(Indicators!$C$2:$C$46, MATCH($A12, Indicators!$A$2:$A$46, 0)) | C12: =INDEX(Indicators!$B$2:$B$46, MATCH($A12, Indicators!$A$2:$A$46, 0)) | D12: =IFERROR(INDEX(Inputs!$B$7:$B$51, MATCH($A12, Inputs!$A$7:$A$51, 0)),"") | E12: =IF($D12="","",IF(AND(INDEX(Indicators!$Q$2:$Q$46, MATCH($A12, Indicators!$A$2:$A$46, 0))="",INDEX(Indicators!$R$2:$R$46, MATCH($A12, Indicators!$A$2:$A$46, 0))=""),$D12,IF(INDEX(Indicators!$Q$2:$Q$46, MATCH($A12, Indicators!$A$2:$A$46, 0))="",MIN($D12,INDEX(Indicators!$R$2:$R$46, MATCH($A12, Indicators!$A$2:$A$46, 0))),IF(INDEX(Indicators!$R$2:$R$46, MATCH($A12, Indicators!$A$2:$A$46, 0))="",MAX($D12,INDEX(Indicators!$Q$2:$Q$46, MATCH($A12, Indicators!$A$2:$A$46, 0))),MIN(MAX($D12,INDEX(Indicators!$Q$2:$Q$46, MATCH($A12, Indicators!$A$2:$A$46, 0))),INDEX(Indicators!$R$2:$R$46, MATCH($A12, Indicators!$A$2:$A$46, 0))))))) | F12: =IF($E12="","",IF(INDEX(Indicators!$I$2:$I$46, MATCH($A12, Indicators!$A$2:$A$46, 0))="TargetBand",IF(AND($E12>=INDEX(Indicators!$N$2:$N$46, MATCH($A12, Indicators!$A$2:$A$46, 0)),$E12<=INDEX(Indicators!$O$2:$O$46, MATCH($A12, Indicators!$A$2:$A$46, 0))),100,IF($E12<INDEX(Indicators!$N$2:$N$46, MATCH($A12, Indicators!$A$2:$A$46, 0)),MAX(0,MIN(100,($E12-INDEX(Indicators!$M$2:$M$46, MATCH($A12, Indicators!$A$2:$A$46, 0)))/(INDEX(Indicators!$N$2:$N$46, MATCH($A12, Indicators!$A$2:$A$46, 0))-INDEX(Indicators!$M$2:$M$46, MATCH($A12, Indicators!$A$2:$A$46, 0)))*100)),MAX(0,MIN(100,(INDEX(Indicators!$P$2:$P$46, MATCH($A12, Indicators!$A$2:$A$46, 0))-$E12)/(INDEX(Indicators!$P$2:$P$46, MATCH($A12, Indicators!$A$2:$A$46, 0))-INDEX(Indicators!$O$2:$O$46, MATCH($A12, Indicators!$A$2:$A$46, 0)))*100)))),IF(INDEX(Indicators!$J$2:$J$46, MATCH($A12, Indicators!$A$2:$A$46, 0))="HigherBetter",MAX(0,MIN(100,($E12-INDEX(Indicators!$L$2:$L$46, MATCH($A12, Indicators!$A$2:$A$46, 0)))/(INDEX(Indicators!$K$2:$K$46, MATCH($A12, Indicators!$A$2:$A$46, 0))-INDEX(Indicators!$L$2:$L$46, MATCH($A12, Indicators!$A$2:$A$46, 0)))*100)),IF(INDEX(Indicators!$J$2:$J$46, MATCH($A12, Indicators!$A$2:$A$46, 0))="LowerBetter",MAX(0,MIN(100,(INDEX(Indicators!$L$2:$L$46, MATCH($A12, Indicators!$A$2:$A$46, 0))-$E12)/(INDEX(Indicators!$L$2:$L$46, MATCH($A12, Indicators!$A$2:$A$46, 0))-INDEX(Indicators!$K$2:$K$46, MATCH($A12, Indicators!$A$2:$A$46, 0)))*100)),"")))) | G12: =IFERROR(INDEX(Indicators!$S$2:$S$46, MATCH($A12, Indicators!$A$2:$A$46, 0)),"") | H12: =IF($F12="","",$F12*$G12) | I12: =IFERROR(INDEX(Indicators!$G$2:$G$46, MATCH($A12, Indicators!$A$2:$A$46, 0)),"")
A13: LEI | B13: =INDEX(Indicators!$C$2:$C$46, MATCH($A13, Indicators!$A$2:$A$46, 0)) | C13: =INDEX(Indicators!$B$2:$B$46, MATCH($A13, Indicators!$A$2:$A$46, 0)) | D13: =IFERROR(INDEX(Inputs!$B$7:$B$51, MATCH($A13, Inputs!$A$7:$A$51, 0)),"") | E13: =IF($D13="","",IF(AND(INDEX(Indicators!$Q$2:$Q$46, MATCH($A13, Indicators!$A$2:$A$46, 0))="",INDEX(Indicators!$R$2:$R$46, MATCH($A13, Indicators!$A$2:$A$46, 0))=""),$D13,IF(INDEX(Indicators!$Q$2:$Q$46, MATCH($A13, Indicators!$A$2:$A$46, 0))="",MIN($D13,INDEX(Indicators!$R$2:$R$46, MATCH($A13, Indicators!$A$2:$A$46, 0))),IF(INDEX(Indicators!$R$2:$R$46, MATCH($A13, Indicators!$A$2:$A$46, 0))="",MAX($D13,INDEX(Indicators!$Q$2:$Q$46, MATCH($A13, Indicators!$A$2:$A$46, 0))),MIN(MAX($D13,INDEX(Indicators!$Q$2:$Q$46, MATCH($A13, Indicators!$A$2:$A$46, 0))),INDEX(Indicators!$R$2:$R$46, MATCH($A13, Indicators!$A$2:$A$46, 0))))))) | F13: =IF($E13="","",IF(INDEX(Indicators!$I$2:$I$46, MATCH($A13, Indicators!$A$2:$A$46, 0))="TargetBand",IF(AND($E13>=INDEX(Indicators!$N$2:$N$46, MATCH($A13, Indicators!$A$2:$A$46, 0)),$E13<=INDEX(Indicators!$O$2:$O$46, MATCH($A13, Indicators!$A$2:$A$46, 0))),100,IF($E13<INDEX(Indicators!$N$2:$N$46, MATCH($A13, Indicators!$A$2:$A$46, 0)),MAX(0,MIN(100,($E13-INDEX(Indicators!$M$2:$M$46, MATCH($A13, Indicators!$A$2:$A$46, 0)))/(INDEX(Indicators!$N$2:$N$46, MATCH($A13, Indicators!$A$2:$A$46, 0))-INDEX(Indicators!$M$2:$M$46, MATCH($A13, Indicators!$A$2:$A$46, 0)))*100)),MAX(0,MIN(100,(INDEX(Indicators!$P$2:$P$46, MATCH($A13, Indicators!$A$2:$A$46, 0))-$E13)/(INDEX(Indicators!$P$2:$P$46, MATCH($A13, Indicators!$A$2:$A$46, 0))-INDEX(Indicators!$O$2:$O$46, MATCH($A13, Indicators!$A$2:$A$46, 0)))*100)))),IF(INDEX(Indicators!$J$2:$J$46, MATCH($A13, Indicators!$A$2:$A$46, 0))="HigherBetter",MAX(0,MIN(100,($E13-INDEX(Indicators!$L$2:$L$46, MATCH($A13, Indicators!$A$2:$A$46, 0)))/(INDEX(Indicators!$K$2:$K$46, MATCH($A13, Indicators!$A$2:$A$46, 0))-INDEX(Indicators!$L$2:$L$46, MATCH($A13, Indicators!$A$2:$A$46, 0)))*100)),IF(INDEX(Indicators!$J$2:$J$46, MATCH($A13, Indicators!$A$2:$A$46, 0))="LowerBetter",MAX(0,MIN(100,(INDEX(Indicators!$L$2:$L$46, MATCH($A13, Indicators!$A$2:$A$46, 0))-$E13)/(INDEX(Indicators!$L$2:$L$46, MATCH($A13, Indicators!$A$2:$A$46, 0))-INDEX(Indicators!$K$2:$K$46, MATCH($A13, Indicators!$A$2:$A$46, 0)))*100)),"")))) | G13: =IFERROR(INDEX(Indicators!$S$2:$S$46, MATCH($A13, Indicators!$A$2:$A$46, 0)),"") | H13: =IF($F13="","",$F13*$G13) | I13: =IFERROR(INDEX(Indicators!$G$2:$G$46, MATCH($A13, Indicators!$A$2:$A$46, 0)),"")
A14: CORE_CPI_YOY | B14: =INDEX(Indicators!$C$2:$C$46, MATCH($A14, Indicators!$A$2:$A$46, 0)) | C14: =INDEX(Indicators!$B$2:$B$46, MATCH($A14, Indicators!$A$2:$A$46, 0)) | D14: =IFERROR(INDEX(Inputs!$B$7:$B$51, MATCH($A14, Inputs!$A$7:$A$51, 0)),"") | E14: =IF($D14="","",IF(AND(INDEX(Indicators!$Q$2:$Q$46, MATCH($A14, Indicators!$A$2:$A$46, 0))="",INDEX(Indicators!$R$2:$R$46, MATCH($A14, Indicators!$A$2:$A$46, 0))=""),$D14,IF(INDEX(Indicators!$Q$2:$Q$46, MATCH($A14, Indicators!$A$2:$A$46, 0))="",MIN($D14,INDEX(Indicators!$R$2:$R$46, MATCH($A14, Indicators!$A$2:$A$46, 0))),IF(INDEX(Indicators!$R$2:$R$46, MATCH($A14, Indicators!$A$2:$A$46, 0))="",MAX($D14,INDEX(Indicators!$Q$2:$Q$46, MATCH($A14, Indicators!$A$2:$A$46, 0))),MIN(MAX($D14,INDEX(Indicators!$Q$2:$Q$46, MATCH($A14, Indicators!$A$2:$A$46, 0))),INDEX(Indicators!$R$2:$R$46, MATCH($A14, Indicators!$A$2:$A$46, 0))))))) | F14: =IF($E14="","",IF(INDEX(Indicators!$I$2:$I$46, MATCH($A14, Indicators!$A$2:$A$46, 0))="TargetBand",IF(AND($E14>=INDEX(Indicators!$N$2:$N$46, MATCH($A14, Indicators!$A$2:$A$46, 0)),$E14<=INDEX(Indicators!$O$2:$O$46, MATCH($A14, Indicators!$A$2:$A$46, 0))),100,IF($E14<INDEX(Indicators!$N$2:$N$46, MATCH($A14, Indicators!$A$2:$A$46, 0)),MAX(0,MIN(100,($E14-INDEX(Indicators!$M$2:$M$46, MATCH($A14, Indicators!$A$2:$A$46, 0)))/(INDEX(Indicators!$N$2:$N$46, MATCH($A14, Indicators!$A$2:$A$46, 0))-INDEX(Indicators!$M$2:$M$46, MATCH($A14, Indicators!$A$2:$A$46, 0)))*100)),MAX(0,MIN(100,(INDEX(Indicators!$P$2:$P$46, MATCH($A14, Indicators!$A$2:$A$46, 0))-$E14)/(INDEX(Indicators!$P$2:$P$46, MATCH($A14, Indicators!$A$2:$A$46, 0))-INDEX(Indicators!$O$2:$O$46, MATCH($A14, Indicators!$A$2:$A$46, 0)))*100)))),IF(INDEX(Indicators!$J$2:$J$46, MATCH($A14, Indicators!$A$2:$A$46, 0))="HigherBetter",MAX(0,MIN(100,($E14-INDEX(Indicators!$L$2:$L$46, MATCH($A14, Indicators!$A$2:$A$46, 0)))/(INDEX(Indicators!$K$2:$K$46, MATCH($A14, Indicators!$A$2:$A$46, 0))-INDEX(Indicators!$L$2:$L$46, MATCH($A14, Indicators!$A$2:$A$46, 0)))*100)),IF(INDEX(Indicators!$J$2:$J$46, MATCH($A14, Indicators!$A$2:$A$46, 0))="LowerBetter",MAX(0,MIN(100,(INDEX(Indicators!$L$2:$L$46, MATCH($A14, Indicators!$A$2:$A$46, 0))-$E14)/(INDEX(Indicators!$L$2:$L$46, MATCH($A14, Indicators!$A$2:$A$46, 0))-INDEX(Indicators!$K$2:$K$46, MATCH($A14, Indicators!$A$2:$A$46, 0)))*100)),"")))) | G14: =IFERROR(INDEX(Indicators!$S$2:$S$46, MATCH($A14, Indicators!$A$2:$A$46, 0)),"") | H14: =IF($F14="","",$F14*$G14) | I14: =IFERROR(INDEX(Indicators!$G$2:$G$46, MATCH($A14, Indicators!$A$2:$A$46, 0)),"")
A15: CORE_PCE_YOY | B15: =INDEX(Indicators!$C$2:$C$46, MATCH($A15, Indicators!$A$2:$A$46, 0)) | C15: =INDEX(Indicators!$B$2:$B$46, MATCH($A15, Indicators!$A$2:$A$46, 0)) | D15: =IFERROR(INDEX(Inputs!$B$7:$B$51, MATCH($A15, Inputs!$A$7:$A$51, 0)),"") | E15: =IF($D15="","",IF(AND(INDEX(Indicators!$Q$2:$Q$46, MATCH($A15, Indicators!$A$2:$A$46, 0))="",INDEX(Indicators!$R$2:$R$46, MATCH($A15, Indicators!$A$2:$A$46, 0))=""),$D15,IF(INDEX(Indicators!$Q$2:$Q$46, MATCH($A15, Indicators!$A$2:$A$46, 0))="",MIN($D15,INDEX(Indicators!$R$2:$R$46, MATCH($A15, Indicators!$A$2:$A$46, 0))),IF(INDEX(Indicators!$R$2:$R$46, MATCH($A15, Indicators!$A$2:$A$46, 0))="",MAX($D15,INDEX(Indicators!$Q$2:$Q$46, MATCH($A15, Indicators!$A$2:$A$46, 0))),MIN(MAX($D15,INDEX(Indicators!$Q$2:$Q$46, MATCH($A15, Indicators!$A$2:$A$46, 0))),INDEX(Indicators!$R$2:$R$46, MATCH($A15, Indicators!$A$2:$A$46, 0))))))) | F15: =IF($E15="","",IF(INDEX(Indicators!$I$2:$I$46, MATCH($A15, Indicators!$A$2:$A$46, 0))="TargetBand",IF(AND($E15>=INDEX(Indicators!$N$2:$N$46, MATCH($A15, Indicators!$A$2:$A$46, 0)),$E15<=INDEX(Indicators!$O$2:$O$46, MATCH($A15, Indicators!$A$2:$A$46, 0))),100,IF($E15<INDEX(Indicators!$N$2:$N$46, MATCH($A15, Indicators!$A$2:$A$46, 0)),MAX(0,MIN(100,($E15-INDEX(Indicators!$M$2:$M$46, MATCH($A15, Indicators!$A$2:$A$46, 0)))/(INDEX(Indicators!$N$2:$N$46, MATCH($A15, Indicators!$A$2:$A$46, 0))-INDEX(Indicators!$M$2:$M$46, MATCH($A15, Indicators!$A$2:$A$46, 0)))*100)),MAX(0,MIN(100,(INDEX(Indicators!$P$2:$P$46, MATCH($A15, Indicators!$A$2:$A$46, 0))-$E15)/(INDEX(Indicators!$P$2:$P$46, MATCH($A15, Indicators!$A$2:$A$46, 0))-INDEX(Indicators!$O$2:$O$46, MATCH($A15, Indicators!$A$2:$A$46, 0)))*100)))),IF(INDEX(Indicators!$J$2:$J$46, MATCH($A15, Indicators!$A$2:$A$46, 0))="HigherBetter",MAX(0,MIN(100,($E15-INDEX(Indicators!$L$2:$L$46, MATCH($A15, Indicators!$A$2:$A$46, 0)))/(INDEX(Indicators!$K$2:$K$46, MATCH($A15, Indicators!$A$2:$A$46, 0))-INDEX(Indicators!$L$2:$L$46, MATCH($A15, Indicators!$A$2:$A$46, 0)))*100)),IF(INDEX(Indicators!$J$2:$J$46, MATCH($A15, Indicators!$A$2:$A$46, 0))="LowerBetter",MAX(0,MIN(100,(INDEX(Indicators!$L$2:$L$46, MATCH($A15, Indicators!$A$2:$A$46, 0))-$E15)/(INDEX(Indicators!$L$2:$L$46, MATCH($A15, Indicators!$A$2:$A$46, 0))-INDEX(Indicators!$K$2:$K$46, MATCH($A15, Indicators!$A$2:$A$46, 0)))*100)),"")))) | G15: =IFERROR(INDEX(Indicators!$S$2:$S$46, MATCH($A15, Indicators!$A$2:$A$46, 0)),"") | H15: =IF($F15="","",$F15*$G15) | I15: =IFERROR(INDEX(Indicators!$G$2:$G$46, MATCH($A15, Indicators!$A$2:$A$46, 0)),"")
A16: BREAKEVEN_5Y5Y | B16: =INDEX(Indicators!$C$2:$C$46, MATCH($A16, Indicators!$A$2:$A$46, 0)) | C16: =INDEX(Indicators!$B$2:$B$46, MATCH($A16, Indicators!$A$2:$A$46, 0)) | D16: =IFERROR(INDEX(Inputs!$B$7:$B$51, MATCH($A16, Inputs!$A$7:$A$51, 0)),"") | E16: =IF($D16="","",IF(AND(INDEX(Indicators!$Q$2:$Q$46, MATCH($A16, Indicators!$A$2:$A$46, 0))="",INDEX(Indicators!$R$2:$R$46, MATCH($A16, Indicators!$A$2:$A$46, 0))=""),$D16,IF(INDEX(Indicators!$Q$2:$Q$46, MATCH($A16, Indicators!$A$2:$A$46, 0))="",MIN($D16,INDEX(Indicators!$R$2:$R$46, MATCH($A16, Indicators!$A$2:$A$46, 0))),IF(INDEX(Indicators!$R$2:$R$46, MATCH($A16, Indicators!$A$2:$A$46, 0))="",MAX($D16,INDEX(Indicators!$Q$2:$Q$46, MATCH($A16, Indicators!$A$2:$A$46, 0))),MIN(MAX($D16,INDEX(Indicators!$Q$2:$Q$46, MATCH($A16, Indicators!$A$2:$A$46, 0))),INDEX(Indicators!$R$2:$R$46, MATCH($A16, Indicators!$A$2:$A$46, 0))))))) | F16: =IF($E16="","",IF(INDEX(Indicators!$I$2:$I$46, MATCH($A16, Indicators!$A$2:$A$46, 0))="TargetBand",IF(AND($E16>=INDEX(Indicators!$N$2:$N$46, MATCH($A16, Indicators!$A$2:$A$46, 0)),$E16<=INDEX(Indicators!$O$2:$O$46, MATCH($A16, Indicators!$A$2:$A$46, 0))),100,IF($E16<INDEX(Indicators!$N$2:$N$46, MATCH($A16, Indicators!$A$2:$A$46, 0)),MAX(0,MIN(100,($E16-INDEX(Indicators!$M$2:$M$46, MATCH($A16, Indicators!$A$2:$A$46, 0)))/(INDEX(Indicators!$N$2:$N$46, MATCH($A16, Indicators!$A$2:$A$46, 0))-INDEX(Indicators!$M$2:$M$46, MATCH($A16, Indicators!$A$2:$A$46, 0)))*100)),MAX(0,MIN(100,(INDEX(Indicators!$P$2:$P$46, MATCH($A16, Indicators!$A$2:$A$46, 0))-$E16)/(INDEX(Indicators!$P$2:$P$46, MATCH($A16, Indicators!$A$2:$A$46, 0))-INDEX(Indicators!$O$2:$O$46, MATCH($A16, Indicators!$A$2:$A$46, 0)))*100)))),IF(INDEX(Indicators!$J$2:$J$46, MATCH($A16, Indicators!$A$2:$A$46, 0))="HigherBetter",MAX(0,MIN(100,($E16-INDEX(Indicators!$L$2:$L$46, MATCH($A16, Indicators!$A$2:$A$46, 0)))/(INDEX(Indicators!$K$2:$K$46, MATCH($A16, Indicators!$A$2:$A$46, 0))-INDEX(Indicators!$L$2:$L$46, MATCH($A16, Indicators!$A$2:$A$46, 0)))*100)),IF(INDEX(Indicators!$J$2:$J$46, MATCH($A16, Indicators!$A$2:$A$46, 0))="LowerBetter",MAX(0,MIN(100,(INDEX(Indicators!$L$2:$L$46, MATCH($A16, Indicators!$A$2:$A$46, 0))-$E16)/(INDEX(Indicators!$L$2:$L$46, MATCH($A16, Indicators!$A$2:$A$46, 0))-INDEX(Indicators!$K$2:$K$46, MATCH($A16, Indicators!$A$2:$A$46, 0)))*100)),"")))) | G16: =IFERROR(INDEX(Indicators!$S$2:$S$46, MATCH($A16, Indicators!$A$2:$A$46, 0)),"") | H16: =IF($F16="","",$F16*$G16) | I16: =IFERROR(INDEX(Indicators!$G$2:$G$46, MATCH($A16, Indicators!$A$2:$A$46, 0)),"")
